<mujoco>
<option gravity="0 0 -9.81" integrator = "RK4"/>

    <asset>
        <mesh name="camera_mesh" file="camera.stl" scale="0.01 0.01 0.01"/>
    </asset>



	<worldbody>
    <light diffuse=".5 .5 .5" pos="0 0 3" dir="0 0 -1"/>
	<geom type="plane" size="2.5 2.5 0.1" rgba=".9 .9 .9 1" pos="0 0 0"/>
		<body name="vertLink" pos="0 0 1.2" xyaxes="1 0 0 0 0 1">
		<!-- <inertial mass="1" pos="0 0 0.25" fullinertia="1 1 0.1 0 0 0"/> -->
		<joint name="joint1" type="hinge" axis="0 1 0" pos="0 -1.2 0"/>
		<geom type="cylinder" size=".05 0.6" pos="0 -.6 0" xyaxes="1 0 0 0 0 -1" rgba="0.9 0 0 0.7"/>
			  <body name="frame2" pos="0 0 .8" xyaxes="1 0 0 0 0 1">
			<!-- <inertial mass="1" pos="0 0 0" fullinertia="1 .1 1 0 0 0"/> -->
			    <joint name="joint2" type="hinge" axis="0 1 0" pos="0 -.8  0 "/>
                <geom type="cylinder" size=".05 0.4" pos="0 -0.4 0 " xyaxes="1 0 0 0 0 -1" rgba="0 0.9 0 0.7"/>
                    <body name="end-effector" pos="0 0 0.8" xyaxes="0 -1 0 1 0 0">
                    <!-- <inertial mass="10" pos="0 0 0" fullinertia="1 1 0.1 0 0 0"/> -->
                    <!-- <site name="body2sensor" pos="0 0 0.0" rgba="1 0 0 1" size="0.0005 0.0005 0.0005" type="sphere"/> -->
                    <geom type="cylinder" size=".05 0.4" pos="0 0 -0.4" rgba="0 0.9 0 .7"/>
                    <!-- <geom type="mesh" mesh="camera_mesh" rgba="1 1 1 1" euler="-90 90 0" pos="-.1 .1 -.54"/> -->
                    </body>
			</body>
		</body>
	</worldbody>
	<!-- <sensor>
        <velocimeter name="body3vel" site="body3sensor"/>
		<gyro name="body3ang" site="body3sensor"/>
		<framelinvel name="spatial3vel" objtype="site" objname="body3sensor" reftype="body" refname="world"/>
		<frameangvel name="spatial3ang" objtype="site" objname="body3sensor" reftype="body" refname="world"/>
        <velocimeter name="body2vel" site="body2sensor"/>
		<gyro name="body2ang" site="body2sensor"/>
		<framelinvel name="spatial2vel" objtype="site" objname="body2sensor" reftype="body" refname="world"/>
		<frameangvel name="spatial2ang" objtype="site" objname="body2sensor" reftype="body" refname="world"/>
	</sensor> -->
	<keyframe>
	<key name="home" qpos="2.6179938 -1.34639"/><!-- theta1, theta2-->
	</keyframe>
</mujoco>


			