<mujoco>
<option gravity="0 0 -9.81" integrator = "RK4"/>

    <asset>
        <mesh name="camera_mesh" file="camera.stl" scale="0.01 0.01 0.01"/>
    </asset>



	<worldbody>
		<light diffuse=".5 .5 .5" pos="0 0 3" dir="0 0 -1"/>
		<geom type="plane" size="2.5 2.5 0.1" rgba=".9 .9 .9 1" pos="0 0 0"/>
		<body name="frame1" pos="0 0 1.2" xyaxes="1 0 0 0 0 1">

			<inertial mass=".01" pos="0 0 0.25" fullinertia="1 1 0.1 0 0 0"/>
			<joint name="joint1" type="hinge" axis="0 1 0" pos="0 -1.2 0"/>
			<geom type="cylinder" size=".05 0.6" pos="0 -.6 0" xyaxes="1 0 0 0 0 -1" rgba="0.9 0 0 0.7"/>
			<body name="frame2" pos="0 0 .8" xyaxes="1 0 0 0 0 1">
				<inertial mass="1" pos="0 0 0" fullinertia="1 .1 1 0 0 0"/>
				<joint name="joint2" type="hinge" axis="0 1 0" pos="0 -.8  0 "/>
				<geom type="cylinder" size=".05 0.4" pos="0 -0.4 0 " xyaxes="1 0 0 0 0 -1" rgba="0 0.9 0 0.7"/>
				<body name="end-effector" pos="0 0 0.8" xyaxes="0 -1 0 1 0 0">
					<inertial mass="100" pos="0 0 0" fullinertia="1 1 0.1 0 0 0"/>
					<site name="end-effector-sensor" pos="0 0 0" size=".005" rgba="1 0 0 1" type="sphere"/>
					<site name="end-effector_spatial_lin_vel-sensor" pos=".8 0 .4" size=".005" rgba="1 0 0 1" type="sphere"/>
					<geom type="cylinder" size=".05 0.4" pos="0 0 -0.4" rgba="0 0.9 0 .7"/>
					<!-- <geom type="mesh" mesh="camera_mesh" rgba="1 1 1 1" euler="-90 90 0" pos="-.1 .1 -.54"/> -->
				</body>
			</body>
		</body>
	</worldbody>
	
	<sensor>
		<!-- Spatial velocities: expressed in the world frame -->
		<framelinvel name="spatial-linear-vel" objtype="site" objname="end-effector_spatial_lin_vel-sensor" reftype="world" refname="world"/>
		<frameangvel name="spatial-ang-vel" objtype="site" objname="end-effector-sensor" reftype="world" refname="world"/>

		<!-- Body velocities: expressed in the end-effector's (body) frame -->
		<velocimeter name="body-linear-vel" site="end-effector-sensor"/>
		<gyro name="body-ang-vel" site="end-effector-sensor"/>

		<!-- Joint sensors for additional verification -->
		<jointpos name="joint1-position" joint="joint1"/>
		<jointpos name="joint2-position" joint="joint2"/>

		<jointvel name="joint1-velocity" joint="joint1"/>
		<jointvel name="joint2-velocity" joint="joint2"/>

	</sensor>

	<keyframe>
	<key name="home" qpos="1.570796327 0"/><!-- theta1, theta2-->
	<key name="Q1" qpos="2.617993878 -1.346396852"/><!-- theta1, theta2-->
	</keyframe>
</mujoco>


			